<?xml version="1.0" encoding="UTF-8"?>
<!-- Generated by org.testng.reporters.JUnitXMLReporter -->
<testsuite hostname="DNID0694L01" ignored="0" name="Default test" tests="57" failures="10" timestamp="15 Jun 2020 17:53:41 GMT" time="627.768" errors="0">
  <testcase name="@AfterClass afterClass" time="1.035" classname="remoteService.order.TC_Remote_Service_CreateTransaction">
    <failure type="java.lang.NullPointerException">
      <![CDATA[java.lang.NullPointerException
at base.TestBase.deleteTransactionByPhoneNumber(TestBase.java:756)
at remoteService.order.TC_Remote_Service_CreateTransaction.afterClass(TC_Remote_Service_CreateTransaction.java:310)
at sun.reflect.NativeMethodAccessorImpl.invoke0(Native Method)
at sun.reflect.NativeMethodAccessorImpl.invoke(NativeMethodAccessorImpl.java:62)
at sun.reflect.DelegatingMethodAccessorImpl.invoke(DelegatingMethodAccessorImpl.java:43)
at java.lang.reflect.Method.invoke(Method.java:498)
at org.testng.internal.MethodInvocationHelper.invokeMethod(MethodInvocationHelper.java:124)
at org.testng.internal.MethodInvocationHelper.invokeMethodConsideringTimeout(MethodInvocationHelper.java:59)
at org.testng.internal.Invoker.invokeConfigurationMethod(Invoker.java:458)
at org.testng.internal.Invoker.invokeConfigurations(Invoker.java:222)
at org.testng.internal.Invoker.invokeConfigurations(Invoker.java:142)
at org.testng.internal.TestMethodWorker.invokeAfterClassMethods(TestMethodWorker.java:214)
at org.testng.internal.TestMethodWorker.run(TestMethodWorker.java:111)
at org.testng.TestRunner.privateRun(TestRunner.java:648)
at org.testng.TestRunner.run(TestRunner.java:505)
at org.testng.SuiteRunner.runTest(SuiteRunner.java:455)
at org.testng.SuiteRunner.runSequentially(SuiteRunner.java:450)
at org.testng.SuiteRunner.privateRun(SuiteRunner.java:415)
at org.testng.SuiteRunner.run(SuiteRunner.java:364)
at org.testng.SuiteRunnerWorker.runSuite(SuiteRunnerWorker.java:52)
at org.testng.SuiteRunnerWorker.run(SuiteRunnerWorker.java:84)
at org.testng.TestNG.runSuitesSequentially(TestNG.java:1208)
at org.testng.TestNG.runSuitesLocally(TestNG.java:1137)
at org.testng.TestNG.runSuites(TestNG.java:1049)
at org.testng.TestNG.run(TestNG.java:1017)
at org.testng.remote.AbstractRemoteTestNG.run(AbstractRemoteTestNG.java:115)
at org.testng.remote.RemoteTestNG.initAndRun(RemoteTestNG.java:251)
at org.testng.remote.RemoteTestNG.main(RemoteTestNG.java:77)
]]>
    </failure>
  </testcase> <!-- @AfterClass afterClass -->
  <testcase name="@AfterClass afterClass" time="0.0" classname="remoteService.order.TC_Remote_Service_CreateTransaction">
    <skipped/>
  </testcase> <!-- @AfterClass afterClass -->
  <testcase name="@AfterClass afterClass" time="0.0" classname="remoteService.order.TC_Remote_Service_CreateTransaction">
    <skipped/>
  </testcase> <!-- @AfterClass afterClass -->
  <testcase name="@AfterClass afterClass" time="0.0" classname="remoteService.order.TC_Remote_Service_CreateTransaction">
    <skipped/>
  </testcase> <!-- @AfterClass afterClass -->
  <testcase name="@AfterClass afterClass" time="0.0" classname="remoteService.order.TC_Remote_Service_CreateTransaction">
    <skipped/>
  </testcase> <!-- @AfterClass afterClass -->
  <testcase name="@AfterClass afterClass" time="0.0" classname="remoteService.order.TC_Remote_Service_CreateTransaction">
    <skipped/>
  </testcase> <!-- @AfterClass afterClass -->
  <testcase name="testCreateTransaction" time="3.447" classname="remoteService.order.TC_Remote_Service_CreateTransaction"/>
  <testcase name="testCreateTransaction" time="2.245" classname="remoteService.order.TC_Remote_Service_CreateTransaction"/>
  <testcase name="testCreateTransaction" time="2.46" classname="remoteService.order.TC_Remote_Service_CreateTransaction"/>
  <testcase name="testCreateTransaction" time="1.642" classname="remoteService.order.TC_Remote_Service_CreateTransaction"/>
  <testcase name="testCreateTransaction" time="2.051" classname="remoteService.order.TC_Remote_Service_CreateTransaction"/>
  <testcase name="testCreateTransaction" time="2.047" classname="remoteService.order.TC_Remote_Service_CreateTransaction"/>
  <testcase name="testCreateTransaction" time="2.057" classname="remoteService.order.TC_Remote_Service_CreateTransaction">
    <failure type="java.lang.AssertionError" message="cannot hit API expected [true] but found [false]">
      <![CDATA[java.lang.AssertionError: cannot hit API expected [true] but found [false]
at org.testng.Assert.fail(Assert.java:96)
at org.testng.Assert.failNotEquals(Assert.java:776)
at org.testng.Assert.assertTrue(Assert.java:44)
at remoteService.order.TC_Remote_Service_CreateTransaction.testCreateTransaction(TC_Remote_Service_CreateTransaction.java:91)
at sun.reflect.NativeMethodAccessorImpl.invoke0(Native Method)
at sun.reflect.NativeMethodAccessorImpl.invoke(NativeMethodAccessorImpl.java:62)
at sun.reflect.DelegatingMethodAccessorImpl.invoke(DelegatingMethodAccessorImpl.java:43)
at java.lang.reflect.Method.invoke(Method.java:498)
at org.testng.internal.MethodInvocationHelper.invokeMethod(MethodInvocationHelper.java:124)
at org.testng.internal.Invoker.invokeMethod(Invoker.java:583)
at org.testng.internal.Invoker.invokeTestMethod(Invoker.java:719)
at org.testng.internal.Invoker.invokeTestMethods(Invoker.java:989)
at org.testng.internal.TestMethodWorker.invokeTestMethods(TestMethodWorker.java:125)
at org.testng.internal.TestMethodWorker.run(TestMethodWorker.java:109)
at org.testng.TestRunner.privateRun(TestRunner.java:648)
at org.testng.TestRunner.run(TestRunner.java:505)
at org.testng.SuiteRunner.runTest(SuiteRunner.java:455)
at org.testng.SuiteRunner.runSequentially(SuiteRunner.java:450)
at org.testng.SuiteRunner.privateRun(SuiteRunner.java:415)
at org.testng.SuiteRunner.run(SuiteRunner.java:364)
at org.testng.SuiteRunnerWorker.runSuite(SuiteRunnerWorker.java:52)
at org.testng.SuiteRunnerWorker.run(SuiteRunnerWorker.java:84)
at org.testng.TestNG.runSuitesSequentially(TestNG.java:1208)
at org.testng.TestNG.runSuitesLocally(TestNG.java:1137)
at org.testng.TestNG.runSuites(TestNG.java:1049)
at org.testng.TestNG.run(TestNG.java:1017)
at org.testng.remote.AbstractRemoteTestNG.run(AbstractRemoteTestNG.java:115)
at org.testng.remote.RemoteTestNG.initAndRun(RemoteTestNG.java:251)
at org.testng.remote.RemoteTestNG.main(RemoteTestNG.java:77)
]]>
    </failure>
  </testcase> <!-- testCreateTransaction -->
  <testcase name="testCreateTransaction" time="2.441" classname="remoteService.order.TC_Remote_Service_CreateTransaction"/>
  <testcase name="testCreateTransaction" time="2.653" classname="remoteService.order.TC_Remote_Service_CreateTransaction"/>
  <testcase name="testCreateTransaction" time="1.8" classname="remoteService.order.TC_Remote_Service_CreateTransaction"/>
  <testcase name="testCreateTransaction" time="1.814" classname="remoteService.order.TC_Remote_Service_CreateTransaction"/>
  <testcase name="testCreateTransaction" time="1.941" classname="remoteService.order.TC_Remote_Service_CreateTransaction"/>
  <testcase name="testCreateTransaction" time="1.989" classname="remoteService.order.TC_Remote_Service_CreateTransaction"/>
  <testcase name="testCreateTransaction" time="1.571" classname="remoteService.order.TC_Remote_Service_CreateTransaction"/>
  <testcase name="testCreateTransaction" time="2.046" classname="remoteService.order.TC_Remote_Service_CreateTransaction"/>
  <testcase name="testCreateTransaction" time="2.525" classname="remoteService.order.TC_Remote_Service_CreateTransaction"/>
  <testcase name="testCreateTransaction" time="1.942" classname="remoteService.order.TC_Remote_Service_CreateTransaction"/>
  <testcase name="testCreateTransaction" time="2.043" classname="remoteService.order.TC_Remote_Service_CreateTransaction"/>
  <testcase name="testCreateTransaction" time="2.641" classname="remoteService.order.TC_Remote_Service_CreateTransaction"/>
  <testcase name="checkData" time="0.001" classname="remoteService.order.TC_Remote_Service_CreateTransaction"/>
  <testcase name="checkData" time="0.001" classname="remoteService.order.TC_Remote_Service_CreateTransaction"/>
  <testcase name="checkData" time="0.0" classname="remoteService.order.TC_Remote_Service_CreateTransaction"/>
  <testcase name="checkData" time="0.001" classname="remoteService.order.TC_Remote_Service_CreateTransaction"/>
  <testcase name="checkData" time="0.002" classname="remoteService.order.TC_Remote_Service_CreateTransaction"/>
  <testcase name="checkData" time="0.003" classname="remoteService.order.TC_Remote_Service_CreateTransaction">
    <failure type="java.lang.AssertionError" message="{&amp;quot;id&amp;quot;:267,&amp;quot;phoneNumber&amp;quot;:&amp;quot;081252930ABC&amp;quot;,&amp;quot;catalog&amp;quot;:{&amp;quot;id&amp;quot;:13,&amp;quot;provider&amp;quot;:{&amp;quot;id&amp;quot;:2,&amp;quot;name&amp;quot;:&amp;quot;Telkomsel&amp;quot;,&amp;quot;image&amp;quot;:&amp;quot;https://res.cloudinary.com/alvark/image/upload/v1592209103/danapulsa/Telkomsel_Logo_eviigt_nbbrjv.png&amp;quot;},&amp;quot;value&amp;quot;:15000,&amp;quot;price&amp;quot;:15000}} expected [true] but found [false]">
      <![CDATA[java.lang.AssertionError: {"id":267,"phoneNumber":"081252930ABC","catalog":{"id":13,"provider":{"id":2,"name":"Telkomsel","image":"https://res.cloudinary.com/alvark/image/upload/v1592209103/danapulsa/Telkomsel_Logo_eviigt_nbbrjv.png"},"value":15000,"price":15000}} expected [true] but found [false]
at org.testng.Assert.fail(Assert.java:96)
at org.testng.Assert.failNotEquals(Assert.java:776)
at org.testng.Assert.assertTrue(Assert.java:44)
at remoteService.order.TC_Remote_Service_CreateTransaction.checkData(TC_Remote_Service_CreateTransaction.java:98)
at sun.reflect.NativeMethodAccessorImpl.invoke0(Native Method)
at sun.reflect.NativeMethodAccessorImpl.invoke(NativeMethodAccessorImpl.java:62)
at sun.reflect.DelegatingMethodAccessorImpl.invoke(DelegatingMethodAccessorImpl.java:43)
at java.lang.reflect.Method.invoke(Method.java:498)
at org.testng.internal.MethodInvocationHelper.invokeMethod(MethodInvocationHelper.java:124)
at org.testng.internal.Invoker.invokeMethod(Invoker.java:583)
at org.testng.internal.Invoker.invokeTestMethod(Invoker.java:719)
at org.testng.internal.Invoker.invokeTestMethods(Invoker.java:989)
at org.testng.internal.TestMethodWorker.invokeTestMethods(TestMethodWorker.java:125)
at org.testng.internal.TestMethodWorker.run(TestMethodWorker.java:109)
at org.testng.TestRunner.privateRun(TestRunner.java:648)
at org.testng.TestRunner.run(TestRunner.java:505)
at org.testng.SuiteRunner.runTest(SuiteRunner.java:455)
at org.testng.SuiteRunner.runSequentially(SuiteRunner.java:450)
at org.testng.SuiteRunner.privateRun(SuiteRunner.java:415)
at org.testng.SuiteRunner.run(SuiteRunner.java:364)
at org.testng.SuiteRunnerWorker.runSuite(SuiteRunnerWorker.java:52)
at org.testng.SuiteRunnerWorker.run(SuiteRunnerWorker.java:84)
at org.testng.TestNG.runSuitesSequentially(TestNG.java:1208)
at org.testng.TestNG.runSuitesLocally(TestNG.java:1137)
at org.testng.TestNG.runSuites(TestNG.java:1049)
at org.testng.TestNG.run(TestNG.java:1017)
at org.testng.remote.AbstractRemoteTestNG.run(AbstractRemoteTestNG.java:115)
at org.testng.remote.RemoteTestNG.initAndRun(RemoteTestNG.java:251)
at org.testng.remote.RemoteTestNG.main(RemoteTestNG.java:77)
]]>
    </failure>
  </testcase> <!-- checkData -->
  <testcase name="checkData" time="0.0" classname="remoteService.order.TC_Remote_Service_CreateTransaction">
    <skipped/>
  </testcase> <!-- checkData -->
  <testcase name="checkData" time="0.001" classname="remoteService.order.TC_Remote_Service_CreateTransaction"/>
  <testcase name="checkData" time="0.001" classname="remoteService.order.TC_Remote_Service_CreateTransaction"/>
  <testcase name="checkData" time="0.001" classname="remoteService.order.TC_Remote_Service_CreateTransaction"/>
  <testcase name="checkData" time="0.001" classname="remoteService.order.TC_Remote_Service_CreateTransaction"/>
  <testcase name="checkData" time="0.001" classname="remoteService.order.TC_Remote_Service_CreateTransaction"/>
  <testcase name="checkData" time="0.003" classname="remoteService.order.TC_Remote_Service_CreateTransaction">
    <failure type="java.lang.AssertionError" message="{&amp;quot;id&amp;quot;:271,&amp;quot;phoneNumber&amp;quot;:&amp;quot;081252930398&amp;quot;,&amp;quot;catalog&amp;quot;:{&amp;quot;id&amp;quot;:13,&amp;quot;provider&amp;quot;:{&amp;quot;id&amp;quot;:2,&amp;quot;name&amp;quot;:&amp;quot;Telkomsel&amp;quot;,&amp;quot;image&amp;quot;:&amp;quot;https://res.cloudinary.com/alvark/image/upload/v1592209103/danapulsa/Telkomsel_Logo_eviigt_nbbrjv.png&amp;quot;},&amp;quot;value&amp;quot;:15000,&amp;quot;price&amp;quot;:15000}} expected [true] but found [false]">
      <![CDATA[java.lang.AssertionError: {"id":271,"phoneNumber":"081252930398","catalog":{"id":13,"provider":{"id":2,"name":"Telkomsel","image":"https://res.cloudinary.com/alvark/image/upload/v1592209103/danapulsa/Telkomsel_Logo_eviigt_nbbrjv.png"},"value":15000,"price":15000}} expected [true] but found [false]
at org.testng.Assert.fail(Assert.java:96)
at org.testng.Assert.failNotEquals(Assert.java:776)
at org.testng.Assert.assertTrue(Assert.java:44)
at remoteService.order.TC_Remote_Service_CreateTransaction.checkData(TC_Remote_Service_CreateTransaction.java:98)
at sun.reflect.NativeMethodAccessorImpl.invoke0(Native Method)
at sun.reflect.NativeMethodAccessorImpl.invoke(NativeMethodAccessorImpl.java:62)
at sun.reflect.DelegatingMethodAccessorImpl.invoke(DelegatingMethodAccessorImpl.java:43)
at java.lang.reflect.Method.invoke(Method.java:498)
at org.testng.internal.MethodInvocationHelper.invokeMethod(MethodInvocationHelper.java:124)
at org.testng.internal.Invoker.invokeMethod(Invoker.java:583)
at org.testng.internal.Invoker.invokeTestMethod(Invoker.java:719)
at org.testng.internal.Invoker.invokeTestMethods(Invoker.java:989)
at org.testng.internal.TestMethodWorker.invokeTestMethods(TestMethodWorker.java:125)
at org.testng.internal.TestMethodWorker.run(TestMethodWorker.java:109)
at org.testng.TestRunner.privateRun(TestRunner.java:648)
at org.testng.TestRunner.run(TestRunner.java:505)
at org.testng.SuiteRunner.runTest(SuiteRunner.java:455)
at org.testng.SuiteRunner.runSequentially(SuiteRunner.java:450)
at org.testng.SuiteRunner.privateRun(SuiteRunner.java:415)
at org.testng.SuiteRunner.run(SuiteRunner.java:364)
at org.testng.SuiteRunnerWorker.runSuite(SuiteRunnerWorker.java:52)
at org.testng.SuiteRunnerWorker.run(SuiteRunnerWorker.java:84)
at org.testng.TestNG.runSuitesSequentially(TestNG.java:1208)
at org.testng.TestNG.runSuitesLocally(TestNG.java:1137)
at org.testng.TestNG.runSuites(TestNG.java:1049)
at org.testng.TestNG.run(TestNG.java:1017)
at org.testng.remote.AbstractRemoteTestNG.run(AbstractRemoteTestNG.java:115)
at org.testng.remote.RemoteTestNG.initAndRun(RemoteTestNG.java:251)
at org.testng.remote.RemoteTestNG.main(RemoteTestNG.java:77)
]]>
    </failure>
  </testcase> <!-- checkData -->
  <testcase name="checkData" time="0.001" classname="remoteService.order.TC_Remote_Service_CreateTransaction"/>
  <testcase name="checkData" time="0.001" classname="remoteService.order.TC_Remote_Service_CreateTransaction"/>
  <testcase name="checkData" time="0.001" classname="remoteService.order.TC_Remote_Service_CreateTransaction"/>
  <testcase name="checkData" time="0.001" classname="remoteService.order.TC_Remote_Service_CreateTransaction"/>
  <testcase name="checkData" time="0.0" classname="remoteService.order.TC_Remote_Service_CreateTransaction"/>
  <testcase name="checkData" time="0.0" classname="remoteService.order.TC_Remote_Service_CreateTransaction"/>
  <testcase name="checkDB" time="4.282" classname="remoteService.order.TC_Remote_Service_CreateTransaction">
    <failure type="java.lang.AssertionError" message="expected [true] but found [false]">
      <![CDATA[java.lang.AssertionError: expected [true] but found [false]
at org.testng.Assert.fail(Assert.java:96)
at org.testng.Assert.failNotEquals(Assert.java:776)
at org.testng.Assert.assertTrue(Assert.java:44)
at org.testng.Assert.assertTrue(Assert.java:54)
at remoteService.order.TC_Remote_Service_CreateTransaction.checkDB(TC_Remote_Service_CreateTransaction.java:277)
at sun.reflect.NativeMethodAccessorImpl.invoke0(Native Method)
at sun.reflect.NativeMethodAccessorImpl.invoke(NativeMethodAccessorImpl.java:62)
at sun.reflect.DelegatingMethodAccessorImpl.invoke(DelegatingMethodAccessorImpl.java:43)
at java.lang.reflect.Method.invoke(Method.java:498)
at org.testng.internal.MethodInvocationHelper.invokeMethod(MethodInvocationHelper.java:124)
at org.testng.internal.Invoker.invokeMethod(Invoker.java:583)
at org.testng.internal.Invoker.invokeTestMethod(Invoker.java:719)
at org.testng.internal.Invoker.invokeTestMethods(Invoker.java:989)
at org.testng.internal.TestMethodWorker.invokeTestMethods(TestMethodWorker.java:125)
at org.testng.internal.TestMethodWorker.run(TestMethodWorker.java:109)
at org.testng.TestRunner.privateRun(TestRunner.java:648)
at org.testng.TestRunner.run(TestRunner.java:505)
at org.testng.SuiteRunner.runTest(SuiteRunner.java:455)
at org.testng.SuiteRunner.runSequentially(SuiteRunner.java:450)
at org.testng.SuiteRunner.privateRun(SuiteRunner.java:415)
at org.testng.SuiteRunner.run(SuiteRunner.java:364)
at org.testng.SuiteRunnerWorker.runSuite(SuiteRunnerWorker.java:52)
at org.testng.SuiteRunnerWorker.run(SuiteRunnerWorker.java:84)
at org.testng.TestNG.runSuitesSequentially(TestNG.java:1208)
at org.testng.TestNG.runSuitesLocally(TestNG.java:1137)
at org.testng.TestNG.runSuites(TestNG.java:1049)
at org.testng.TestNG.run(TestNG.java:1017)
at org.testng.remote.AbstractRemoteTestNG.run(AbstractRemoteTestNG.java:115)
at org.testng.remote.RemoteTestNG.initAndRun(RemoteTestNG.java:251)
at org.testng.remote.RemoteTestNG.main(RemoteTestNG.java:77)
]]>
    </failure>
  </testcase> <!-- checkDB -->
  <testcase name="checkDB" time="5.07" classname="remoteService.order.TC_Remote_Service_CreateTransaction">
    <failure type="java.lang.AssertionError" message="expected [true] but found [false]">
      <![CDATA[java.lang.AssertionError: expected [true] but found [false]
at org.testng.Assert.fail(Assert.java:96)
at org.testng.Assert.failNotEquals(Assert.java:776)
at org.testng.Assert.assertTrue(Assert.java:44)
at org.testng.Assert.assertTrue(Assert.java:54)
at remoteService.order.TC_Remote_Service_CreateTransaction.checkDB(TC_Remote_Service_CreateTransaction.java:277)
at sun.reflect.NativeMethodAccessorImpl.invoke0(Native Method)
at sun.reflect.NativeMethodAccessorImpl.invoke(NativeMethodAccessorImpl.java:62)
at sun.reflect.DelegatingMethodAccessorImpl.invoke(DelegatingMethodAccessorImpl.java:43)
at java.lang.reflect.Method.invoke(Method.java:498)
at org.testng.internal.MethodInvocationHelper.invokeMethod(MethodInvocationHelper.java:124)
at org.testng.internal.Invoker.invokeMethod(Invoker.java:583)
at org.testng.internal.Invoker.invokeTestMethod(Invoker.java:719)
at org.testng.internal.Invoker.invokeTestMethods(Invoker.java:989)
at org.testng.internal.TestMethodWorker.invokeTestMethods(TestMethodWorker.java:125)
at org.testng.internal.TestMethodWorker.run(TestMethodWorker.java:109)
at org.testng.TestRunner.privateRun(TestRunner.java:648)
at org.testng.TestRunner.run(TestRunner.java:505)
at org.testng.SuiteRunner.runTest(SuiteRunner.java:455)
at org.testng.SuiteRunner.runSequentially(SuiteRunner.java:450)
at org.testng.SuiteRunner.privateRun(SuiteRunner.java:415)
at org.testng.SuiteRunner.run(SuiteRunner.java:364)
at org.testng.SuiteRunnerWorker.runSuite(SuiteRunnerWorker.java:52)
at org.testng.SuiteRunnerWorker.run(SuiteRunnerWorker.java:84)
at org.testng.TestNG.runSuitesSequentially(TestNG.java:1208)
at org.testng.TestNG.runSuitesLocally(TestNG.java:1137)
at org.testng.TestNG.runSuites(TestNG.java:1049)
at org.testng.TestNG.run(TestNG.java:1017)
at org.testng.remote.AbstractRemoteTestNG.run(AbstractRemoteTestNG.java:115)
at org.testng.remote.RemoteTestNG.initAndRun(RemoteTestNG.java:251)
at org.testng.remote.RemoteTestNG.main(RemoteTestNG.java:77)
]]>
    </failure>
  </testcase> <!-- checkDB -->
  <testcase name="checkDB" time="4.802" classname="remoteService.order.TC_Remote_Service_CreateTransaction"/>
  <testcase name="checkDB" time="4.711" classname="remoteService.order.TC_Remote_Service_CreateTransaction">
    <failure type="java.lang.AssertionError" message="expected [true] but found [false]">
      <![CDATA[java.lang.AssertionError: expected [true] but found [false]
at org.testng.Assert.fail(Assert.java:96)
at org.testng.Assert.failNotEquals(Assert.java:776)
at org.testng.Assert.assertTrue(Assert.java:44)
at org.testng.Assert.assertTrue(Assert.java:54)
at remoteService.order.TC_Remote_Service_CreateTransaction.checkDB(TC_Remote_Service_CreateTransaction.java:277)
at sun.reflect.NativeMethodAccessorImpl.invoke0(Native Method)
at sun.reflect.NativeMethodAccessorImpl.invoke(NativeMethodAccessorImpl.java:62)
at sun.reflect.DelegatingMethodAccessorImpl.invoke(DelegatingMethodAccessorImpl.java:43)
at java.lang.reflect.Method.invoke(Method.java:498)
at org.testng.internal.MethodInvocationHelper.invokeMethod(MethodInvocationHelper.java:124)
at org.testng.internal.Invoker.invokeMethod(Invoker.java:583)
at org.testng.internal.Invoker.invokeTestMethod(Invoker.java:719)
at org.testng.internal.Invoker.invokeTestMethods(Invoker.java:989)
at org.testng.internal.TestMethodWorker.invokeTestMethods(TestMethodWorker.java:125)
at org.testng.internal.TestMethodWorker.run(TestMethodWorker.java:109)
at org.testng.TestRunner.privateRun(TestRunner.java:648)
at org.testng.TestRunner.run(TestRunner.java:505)
at org.testng.SuiteRunner.runTest(SuiteRunner.java:455)
at org.testng.SuiteRunner.runSequentially(SuiteRunner.java:450)
at org.testng.SuiteRunner.privateRun(SuiteRunner.java:415)
at org.testng.SuiteRunner.run(SuiteRunner.java:364)
at org.testng.SuiteRunnerWorker.runSuite(SuiteRunnerWorker.java:52)
at org.testng.SuiteRunnerWorker.run(SuiteRunnerWorker.java:84)
at org.testng.TestNG.runSuitesSequentially(TestNG.java:1208)
at org.testng.TestNG.runSuitesLocally(TestNG.java:1137)
at org.testng.TestNG.runSuites(TestNG.java:1049)
at org.testng.TestNG.run(TestNG.java:1017)
at org.testng.remote.AbstractRemoteTestNG.run(AbstractRemoteTestNG.java:115)
at org.testng.remote.RemoteTestNG.initAndRun(RemoteTestNG.java:251)
at org.testng.remote.RemoteTestNG.main(RemoteTestNG.java:77)
]]>
    </failure>
  </testcase> <!-- checkDB -->
  <testcase name="checkDB" time="5.65" classname="remoteService.order.TC_Remote_Service_CreateTransaction">
    <failure type="java.lang.AssertionError" message="expected [true] but found [false]">
      <![CDATA[java.lang.AssertionError: expected [true] but found [false]
at org.testng.Assert.fail(Assert.java:96)
at org.testng.Assert.failNotEquals(Assert.java:776)
at org.testng.Assert.assertTrue(Assert.java:44)
at org.testng.Assert.assertTrue(Assert.java:54)
at remoteService.order.TC_Remote_Service_CreateTransaction.checkDB(TC_Remote_Service_CreateTransaction.java:277)
at sun.reflect.NativeMethodAccessorImpl.invoke0(Native Method)
at sun.reflect.NativeMethodAccessorImpl.invoke(NativeMethodAccessorImpl.java:62)
at sun.reflect.DelegatingMethodAccessorImpl.invoke(DelegatingMethodAccessorImpl.java:43)
at java.lang.reflect.Method.invoke(Method.java:498)
at org.testng.internal.MethodInvocationHelper.invokeMethod(MethodInvocationHelper.java:124)
at org.testng.internal.Invoker.invokeMethod(Invoker.java:583)
at org.testng.internal.Invoker.invokeTestMethod(Invoker.java:719)
at org.testng.internal.Invoker.invokeTestMethods(Invoker.java:989)
at org.testng.internal.TestMethodWorker.invokeTestMethods(TestMethodWorker.java:125)
at org.testng.internal.TestMethodWorker.run(TestMethodWorker.java:109)
at org.testng.TestRunner.privateRun(TestRunner.java:648)
at org.testng.TestRunner.run(TestRunner.java:505)
at org.testng.SuiteRunner.runTest(SuiteRunner.java:455)
at org.testng.SuiteRunner.runSequentially(SuiteRunner.java:450)
at org.testng.SuiteRunner.privateRun(SuiteRunner.java:415)
at org.testng.SuiteRunner.run(SuiteRunner.java:364)
at org.testng.SuiteRunnerWorker.runSuite(SuiteRunnerWorker.java:52)
at org.testng.SuiteRunnerWorker.run(SuiteRunnerWorker.java:84)
at org.testng.TestNG.runSuitesSequentially(TestNG.java:1208)
at org.testng.TestNG.runSuitesLocally(TestNG.java:1137)
at org.testng.TestNG.runSuites(TestNG.java:1049)
at org.testng.TestNG.run(TestNG.java:1017)
at org.testng.remote.AbstractRemoteTestNG.run(AbstractRemoteTestNG.java:115)
at org.testng.remote.RemoteTestNG.initAndRun(RemoteTestNG.java:251)
at org.testng.remote.RemoteTestNG.main(RemoteTestNG.java:77)
]]>
    </failure>
  </testcase> <!-- checkDB -->
  <testcase name="checkDB" time="0.0" classname="remoteService.order.TC_Remote_Service_CreateTransaction">
    <skipped/>
  </testcase> <!-- checkDB -->
  <testcase name="checkDB" time="0.0" classname="remoteService.order.TC_Remote_Service_CreateTransaction">
    <skipped/>
  </testcase> <!-- checkDB -->
  <testcase name="checkDB" time="5.168" classname="remoteService.order.TC_Remote_Service_CreateTransaction"/>
  <testcase name="checkDB" time="5.746" classname="remoteService.order.TC_Remote_Service_CreateTransaction"/>
  <testcase name="checkDB" time="5.325" classname="remoteService.order.TC_Remote_Service_CreateTransaction">
    <failure type="java.lang.AssertionError" message="expected [true] but found [false]">
      <![CDATA[java.lang.AssertionError: expected [true] but found [false]
at org.testng.Assert.fail(Assert.java:96)
at org.testng.Assert.failNotEquals(Assert.java:776)
at org.testng.Assert.assertTrue(Assert.java:44)
at org.testng.Assert.assertTrue(Assert.java:54)
at remoteService.order.TC_Remote_Service_CreateTransaction.checkDB(TC_Remote_Service_CreateTransaction.java:277)
at sun.reflect.NativeMethodAccessorImpl.invoke0(Native Method)
at sun.reflect.NativeMethodAccessorImpl.invoke(NativeMethodAccessorImpl.java:62)
at sun.reflect.DelegatingMethodAccessorImpl.invoke(DelegatingMethodAccessorImpl.java:43)
at java.lang.reflect.Method.invoke(Method.java:498)
at org.testng.internal.MethodInvocationHelper.invokeMethod(MethodInvocationHelper.java:124)
at org.testng.internal.Invoker.invokeMethod(Invoker.java:583)
at org.testng.internal.Invoker.invokeTestMethod(Invoker.java:719)
at org.testng.internal.Invoker.invokeTestMethods(Invoker.java:989)
at org.testng.internal.TestMethodWorker.invokeTestMethods(TestMethodWorker.java:125)
at org.testng.internal.TestMethodWorker.run(TestMethodWorker.java:109)
at org.testng.TestRunner.privateRun(TestRunner.java:648)
at org.testng.TestRunner.run(TestRunner.java:505)
at org.testng.SuiteRunner.runTest(SuiteRunner.java:455)
at org.testng.SuiteRunner.runSequentially(SuiteRunner.java:450)
at org.testng.SuiteRunner.privateRun(SuiteRunner.java:415)
at org.testng.SuiteRunner.run(SuiteRunner.java:364)
at org.testng.SuiteRunnerWorker.runSuite(SuiteRunnerWorker.java:52)
at org.testng.SuiteRunnerWorker.run(SuiteRunnerWorker.java:84)
at org.testng.TestNG.runSuitesSequentially(TestNG.java:1208)
at org.testng.TestNG.runSuitesLocally(TestNG.java:1137)
at org.testng.TestNG.runSuites(TestNG.java:1049)
at org.testng.TestNG.run(TestNG.java:1017)
at org.testng.remote.AbstractRemoteTestNG.run(AbstractRemoteTestNG.java:115)
at org.testng.remote.RemoteTestNG.initAndRun(RemoteTestNG.java:251)
at org.testng.remote.RemoteTestNG.main(RemoteTestNG.java:77)
]]>
    </failure>
  </testcase> <!-- checkDB -->
  <testcase name="checkDB" time="16.234" classname="remoteService.order.TC_Remote_Service_CreateTransaction">
    <failure type="java.lang.AssertionError" message="expected [true] but found [false]">
      <![CDATA[java.lang.AssertionError: expected [true] but found [false]
at org.testng.Assert.fail(Assert.java:96)
at org.testng.Assert.failNotEquals(Assert.java:776)
at org.testng.Assert.assertTrue(Assert.java:44)
at org.testng.Assert.assertTrue(Assert.java:54)
at remoteService.order.TC_Remote_Service_CreateTransaction.checkDB(TC_Remote_Service_CreateTransaction.java:258)
at sun.reflect.NativeMethodAccessorImpl.invoke0(Native Method)
at sun.reflect.NativeMethodAccessorImpl.invoke(NativeMethodAccessorImpl.java:62)
at sun.reflect.DelegatingMethodAccessorImpl.invoke(DelegatingMethodAccessorImpl.java:43)
at java.lang.reflect.Method.invoke(Method.java:498)
at org.testng.internal.MethodInvocationHelper.invokeMethod(MethodInvocationHelper.java:124)
at org.testng.internal.Invoker.invokeMethod(Invoker.java:583)
at org.testng.internal.Invoker.invokeTestMethod(Invoker.java:719)
at org.testng.internal.Invoker.invokeTestMethods(Invoker.java:989)
at org.testng.internal.TestMethodWorker.invokeTestMethods(TestMethodWorker.java:125)
at org.testng.internal.TestMethodWorker.run(TestMethodWorker.java:109)
at org.testng.TestRunner.privateRun(TestRunner.java:648)
at org.testng.TestRunner.run(TestRunner.java:505)
at org.testng.SuiteRunner.runTest(SuiteRunner.java:455)
at org.testng.SuiteRunner.runSequentially(SuiteRunner.java:450)
at org.testng.SuiteRunner.privateRun(SuiteRunner.java:415)
at org.testng.SuiteRunner.run(SuiteRunner.java:364)
at org.testng.SuiteRunnerWorker.runSuite(SuiteRunnerWorker.java:52)
at org.testng.SuiteRunnerWorker.run(SuiteRunnerWorker.java:84)
at org.testng.TestNG.runSuitesSequentially(TestNG.java:1208)
at org.testng.TestNG.runSuitesLocally(TestNG.java:1137)
at org.testng.TestNG.runSuites(TestNG.java:1049)
at org.testng.TestNG.run(TestNG.java:1017)
at org.testng.remote.AbstractRemoteTestNG.run(AbstractRemoteTestNG.java:115)
at org.testng.remote.RemoteTestNG.initAndRun(RemoteTestNG.java:251)
at org.testng.remote.RemoteTestNG.main(RemoteTestNG.java:77)
]]>
    </failure>
  </testcase> <!-- checkDB -->
  <testcase name="checkDB" time="5.131" classname="remoteService.order.TC_Remote_Service_CreateTransaction"/>
  <testcase name="checkDB" time="0.0" classname="remoteService.order.TC_Remote_Service_CreateTransaction">
    <skipped/>
  </testcase> <!-- checkDB -->
  <testcase name="checkDB" time="5.527" classname="remoteService.order.TC_Remote_Service_CreateTransaction">
    <failure type="java.lang.NumberFormatException" message="For input string: &amp;quot;&amp;quot;">
      <![CDATA[java.lang.NumberFormatException: For input string: ""
at java.lang.NumberFormatException.forInputString(NumberFormatException.java:65)
at java.lang.Long.parseLong(Long.java:601)
at java.lang.Long.parseLong(Long.java:631)
at remoteService.order.TC_Remote_Service_CreateTransaction.checkDB(TC_Remote_Service_CreateTransaction.java:272)
at sun.reflect.NativeMethodAccessorImpl.invoke0(Native Method)
at sun.reflect.NativeMethodAccessorImpl.invoke(NativeMethodAccessorImpl.java:62)
at sun.reflect.DelegatingMethodAccessorImpl.invoke(DelegatingMethodAccessorImpl.java:43)
at java.lang.reflect.Method.invoke(Method.java:498)
at org.testng.internal.MethodInvocationHelper.invokeMethod(MethodInvocationHelper.java:124)
at org.testng.internal.Invoker.invokeMethod(Invoker.java:583)
at org.testng.internal.Invoker.invokeTestMethod(Invoker.java:719)
at org.testng.internal.Invoker.invokeTestMethods(Invoker.java:989)
at org.testng.internal.TestMethodWorker.invokeTestMethods(TestMethodWorker.java:125)
at org.testng.internal.TestMethodWorker.run(TestMethodWorker.java:109)
at org.testng.TestRunner.privateRun(TestRunner.java:648)
at org.testng.TestRunner.run(TestRunner.java:505)
at org.testng.SuiteRunner.runTest(SuiteRunner.java:455)
at org.testng.SuiteRunner.runSequentially(SuiteRunner.java:450)
at org.testng.SuiteRunner.privateRun(SuiteRunner.java:415)
at org.testng.SuiteRunner.run(SuiteRunner.java:364)
at org.testng.SuiteRunnerWorker.runSuite(SuiteRunnerWorker.java:52)
at org.testng.SuiteRunnerWorker.run(SuiteRunnerWorker.java:84)
at org.testng.TestNG.runSuitesSequentially(TestNG.java:1208)
at org.testng.TestNG.runSuitesLocally(TestNG.java:1137)
at org.testng.TestNG.runSuites(TestNG.java:1049)
at org.testng.TestNG.run(TestNG.java:1017)
at org.testng.remote.AbstractRemoteTestNG.run(AbstractRemoteTestNG.java:115)
at org.testng.remote.RemoteTestNG.initAndRun(RemoteTestNG.java:251)
at org.testng.remote.RemoteTestNG.main(RemoteTestNG.java:77)
]]>
    </failure>
  </testcase> <!-- checkDB -->
  <testcase name="checkDB" time="0.0" classname="remoteService.order.TC_Remote_Service_CreateTransaction">
    <skipped/>
  </testcase> <!-- checkDB -->
  <testcase name="checkDB" time="0.0" classname="remoteService.order.TC_Remote_Service_CreateTransaction">
    <skipped/>
  </testcase> <!-- checkDB -->
  <testcase name="checkDB" time="0.0" classname="remoteService.order.TC_Remote_Service_CreateTransaction">
    <skipped/>
  </testcase> <!-- checkDB -->
  <testcase name="checkDB" time="0.0" classname="remoteService.order.TC_Remote_Service_CreateTransaction">
    <skipped/>
  </testcase> <!-- checkDB -->
  <testcase name="checkDB" time="0.0" classname="remoteService.order.TC_Remote_Service_CreateTransaction">
    <skipped/>
  </testcase> <!-- checkDB -->
</testsuite> <!-- Default test -->
