<?xml version="1.0" encoding="UTF-8"?>
<testng-results skipped="3" failed="0" ignored="0" total="3" passed="0">
  <reporter-output>
  </reporter-output>
  <suite name="Default suite" duration-ms="24345" started-at="2020-06-12T08:10:20Z" finished-at="2020-06-12T08:10:44Z">
    <groups>
    </groups>
    <test name="Default test" duration-ms="24345" started-at="2020-06-12T08:10:20Z" finished-at="2020-06-12T08:10:44Z">
      <class name="testCases.order.TC_Recent_Phone_Number">
        <test-method status="PASS" signature="setup()[pri:0, instance:testCases.order.TC_Recent_Phone_Number@3b2cf7ab]" name="setup" is-config="true" duration-ms="84" started-at="2020-06-12T08:10:20Z" finished-at="2020-06-12T08:10:20Z">
          <reporter-output>
          </reporter-output>
        </test-method> <!-- setup -->
        <test-method status="FAIL" signature="beforeClass()[pri:0, instance:testCases.order.TC_Recent_Phone_Number@3b2cf7ab]" name="beforeClass" is-config="true" duration-ms="24224" started-at="2020-06-12T08:10:20Z" finished-at="2020-06-12T08:10:44Z">
          <exception class="java.lang.AssertionError">
            <message>
              <![CDATA[expected:<404> but was:<200>]]>
            </message>
            <full-stacktrace>
              <![CDATA[java.lang.AssertionError: expected:<404> but was:<200>
at org.junit.Assert.fail(Assert.java:88)
at org.junit.Assert.failNotEquals(Assert.java:743)
at org.junit.Assert.assertEquals(Assert.java:118)
at org.junit.Assert.assertEquals(Assert.java:555)
at org.junit.Assert.assertEquals(Assert.java:542)
at base.TestBase.checkStatusCode(TestBase.java:91)
at testCases.order.TC_Recent_Phone_Number.beforeClass(TC_Recent_Phone_Number.java:72)
at sun.reflect.NativeMethodAccessorImpl.invoke0(Native Method)
at sun.reflect.NativeMethodAccessorImpl.invoke(NativeMethodAccessorImpl.java:62)
at sun.reflect.DelegatingMethodAccessorImpl.invoke(DelegatingMethodAccessorImpl.java:43)
at java.lang.reflect.Method.invoke(Method.java:498)
at org.testng.internal.MethodInvocationHelper.invokeMethod(MethodInvocationHelper.java:124)
at org.testng.internal.MethodInvocationHelper.invokeMethodConsideringTimeout(MethodInvocationHelper.java:59)
at org.testng.internal.Invoker.invokeConfigurationMethod(Invoker.java:458)
at org.testng.internal.Invoker.invokeConfigurations(Invoker.java:222)
at org.testng.internal.Invoker.invokeConfigurations(Invoker.java:142)
at org.testng.internal.TestMethodWorker.invokeBeforeClassMethods(TestMethodWorker.java:168)
at org.testng.internal.TestMethodWorker.run(TestMethodWorker.java:105)
at org.testng.TestRunner.privateRun(TestRunner.java:648)
at org.testng.TestRunner.run(TestRunner.java:505)
at org.testng.SuiteRunner.runTest(SuiteRunner.java:455)
at org.testng.SuiteRunner.runSequentially(SuiteRunner.java:450)
at org.testng.SuiteRunner.privateRun(SuiteRunner.java:415)
at org.testng.SuiteRunner.run(SuiteRunner.java:364)
at org.testng.SuiteRunnerWorker.runSuite(SuiteRunnerWorker.java:52)
at org.testng.SuiteRunnerWorker.run(SuiteRunnerWorker.java:84)
at org.testng.TestNG.runSuitesSequentially(TestNG.java:1208)
at org.testng.TestNG.runSuitesLocally(TestNG.java:1137)
at org.testng.TestNG.runSuites(TestNG.java:1049)
at org.testng.TestNG.run(TestNG.java:1017)
at org.testng.remote.AbstractRemoteTestNG.run(AbstractRemoteTestNG.java:115)
at org.testng.remote.RemoteTestNG.initAndRun(RemoteTestNG.java:251)
at org.testng.remote.RemoteTestNG.main(RemoteTestNG.java:77)
]]>
            </full-stacktrace>
          </exception> <!-- java.lang.AssertionError -->
          <reporter-output>
          </reporter-output>
        </test-method> <!-- beforeClass -->
        <test-method status="SKIP" signature="testRecentPhoneNumber()[pri:0, instance:testCases.order.TC_Recent_Phone_Number@3b2cf7ab]" name="testRecentPhoneNumber" duration-ms="0" started-at="2020-06-12T08:10:44Z" finished-at="2020-06-12T08:10:44Z">
          <exception class="java.lang.AssertionError">
            <message>
              <![CDATA[expected:<404> but was:<200>]]>
            </message>
            <full-stacktrace>
              <![CDATA[java.lang.AssertionError: expected:<404> but was:<200>
at org.junit.Assert.fail(Assert.java:88)
at org.junit.Assert.failNotEquals(Assert.java:743)
at org.junit.Assert.assertEquals(Assert.java:118)
at org.junit.Assert.assertEquals(Assert.java:555)
at org.junit.Assert.assertEquals(Assert.java:542)
at base.TestBase.checkStatusCode(TestBase.java:91)
at testCases.order.TC_Recent_Phone_Number.beforeClass(TC_Recent_Phone_Number.java:72)
at sun.reflect.NativeMethodAccessorImpl.invoke0(Native Method)
at sun.reflect.NativeMethodAccessorImpl.invoke(NativeMethodAccessorImpl.java:62)
at sun.reflect.DelegatingMethodAccessorImpl.invoke(DelegatingMethodAccessorImpl.java:43)
at java.lang.reflect.Method.invoke(Method.java:498)
at org.testng.internal.MethodInvocationHelper.invokeMethod(MethodInvocationHelper.java:124)
at org.testng.internal.MethodInvocationHelper.invokeMethodConsideringTimeout(MethodInvocationHelper.java:59)
at org.testng.internal.Invoker.invokeConfigurationMethod(Invoker.java:458)
at org.testng.internal.Invoker.invokeConfigurations(Invoker.java:222)
at org.testng.internal.Invoker.invokeConfigurations(Invoker.java:142)
at org.testng.internal.TestMethodWorker.invokeBeforeClassMethods(TestMethodWorker.java:168)
at org.testng.internal.TestMethodWorker.run(TestMethodWorker.java:105)
at org.testng.TestRunner.privateRun(TestRunner.java:648)
at org.testng.TestRunner.run(TestRunner.java:505)
at org.testng.SuiteRunner.runTest(SuiteRunner.java:455)
at org.testng.SuiteRunner.runSequentially(SuiteRunner.java:450)
at org.testng.SuiteRunner.privateRun(SuiteRunner.java:415)
at org.testng.SuiteRunner.run(SuiteRunner.java:364)
at org.testng.SuiteRunnerWorker.runSuite(SuiteRunnerWorker.java:52)
at org.testng.SuiteRunnerWorker.run(SuiteRunnerWorker.java:84)
at org.testng.TestNG.runSuitesSequentially(TestNG.java:1208)
at org.testng.TestNG.runSuitesLocally(TestNG.java:1137)
at org.testng.TestNG.runSuites(TestNG.java:1049)
at org.testng.TestNG.run(TestNG.java:1017)
at org.testng.remote.AbstractRemoteTestNG.run(AbstractRemoteTestNG.java:115)
at org.testng.remote.RemoteTestNG.initAndRun(RemoteTestNG.java:251)
at org.testng.remote.RemoteTestNG.main(RemoteTestNG.java:77)
]]>
            </full-stacktrace>
          </exception> <!-- java.lang.AssertionError -->
          <reporter-output>
          </reporter-output>
        </test-method> <!-- testRecentPhoneNumber -->
        <test-method status="SKIP" signature="checkData()[pri:0, instance:testCases.order.TC_Recent_Phone_Number@3b2cf7ab]" name="checkData" duration-ms="0" started-at="2020-06-12T08:10:44Z" depends-on-methods="testCases.order.TC_Recent_Phone_Number.testRecentPhoneNumber" finished-at="2020-06-12T08:10:44Z">
          <exception class="java.lang.Throwable">
            <message>
              <![CDATA[Method TC_Recent_Phone_Number.checkData()[pri:0, instance:testCases.order.TC_Recent_Phone_Number@3b2cf7ab] depends on not successfully finished methods]]>
            </message>
            <full-stacktrace>
              <![CDATA[java.lang.Throwable: Method TC_Recent_Phone_Number.checkData()[pri:0, instance:testCases.order.TC_Recent_Phone_Number@3b2cf7ab] depends on not successfully finished methods
at org.testng.internal.Invoker.invokeTestMethods(Invoker.java:888)
at org.testng.internal.TestMethodWorker.invokeTestMethods(TestMethodWorker.java:125)
at org.testng.internal.TestMethodWorker.run(TestMethodWorker.java:109)
at org.testng.TestRunner.privateRun(TestRunner.java:648)
at org.testng.TestRunner.run(TestRunner.java:505)
at org.testng.SuiteRunner.runTest(SuiteRunner.java:455)
at org.testng.SuiteRunner.runSequentially(SuiteRunner.java:450)
at org.testng.SuiteRunner.privateRun(SuiteRunner.java:415)
at org.testng.SuiteRunner.run(SuiteRunner.java:364)
at org.testng.SuiteRunnerWorker.runSuite(SuiteRunnerWorker.java:52)
at org.testng.SuiteRunnerWorker.run(SuiteRunnerWorker.java:84)
at org.testng.TestNG.runSuitesSequentially(TestNG.java:1208)
at org.testng.TestNG.runSuitesLocally(TestNG.java:1137)
at org.testng.TestNG.runSuites(TestNG.java:1049)
at org.testng.TestNG.run(TestNG.java:1017)
at org.testng.remote.AbstractRemoteTestNG.run(AbstractRemoteTestNG.java:115)
at org.testng.remote.RemoteTestNG.initAndRun(RemoteTestNG.java:251)
at org.testng.remote.RemoteTestNG.main(RemoteTestNG.java:77)
]]>
            </full-stacktrace>
          </exception> <!-- java.lang.Throwable -->
          <reporter-output>
          </reporter-output>
        </test-method> <!-- checkData -->
        <test-method status="SKIP" signature="checkDB()[pri:0, instance:testCases.order.TC_Recent_Phone_Number@3b2cf7ab]" name="checkDB" duration-ms="0" started-at="2020-06-12T08:10:44Z" depends-on-methods="testCases.order.TC_Recent_Phone_Number.checkData" finished-at="2020-06-12T08:10:44Z">
          <exception class="java.lang.Throwable">
            <message>
              <![CDATA[Method TC_Recent_Phone_Number.checkDB()[pri:0, instance:testCases.order.TC_Recent_Phone_Number@3b2cf7ab] depends on not successfully finished methods]]>
            </message>
            <full-stacktrace>
              <![CDATA[java.lang.Throwable: Method TC_Recent_Phone_Number.checkDB()[pri:0, instance:testCases.order.TC_Recent_Phone_Number@3b2cf7ab] depends on not successfully finished methods
at org.testng.internal.Invoker.invokeTestMethods(Invoker.java:888)
at org.testng.internal.TestMethodWorker.invokeTestMethods(TestMethodWorker.java:125)
at org.testng.internal.TestMethodWorker.run(TestMethodWorker.java:109)
at org.testng.TestRunner.privateRun(TestRunner.java:648)
at org.testng.TestRunner.run(TestRunner.java:505)
at org.testng.SuiteRunner.runTest(SuiteRunner.java:455)
at org.testng.SuiteRunner.runSequentially(SuiteRunner.java:450)
at org.testng.SuiteRunner.privateRun(SuiteRunner.java:415)
at org.testng.SuiteRunner.run(SuiteRunner.java:364)
at org.testng.SuiteRunnerWorker.runSuite(SuiteRunnerWorker.java:52)
at org.testng.SuiteRunnerWorker.run(SuiteRunnerWorker.java:84)
at org.testng.TestNG.runSuitesSequentially(TestNG.java:1208)
at org.testng.TestNG.runSuitesLocally(TestNG.java:1137)
at org.testng.TestNG.runSuites(TestNG.java:1049)
at org.testng.TestNG.run(TestNG.java:1017)
at org.testng.remote.AbstractRemoteTestNG.run(AbstractRemoteTestNG.java:115)
at org.testng.remote.RemoteTestNG.initAndRun(RemoteTestNG.java:251)
at org.testng.remote.RemoteTestNG.main(RemoteTestNG.java:77)
]]>
            </full-stacktrace>
          </exception> <!-- java.lang.Throwable -->
          <reporter-output>
          </reporter-output>
        </test-method> <!-- checkDB -->
        <test-method status="SKIP" signature="afterClass()[pri:0, instance:testCases.order.TC_Recent_Phone_Number@3b2cf7ab]" name="afterClass" is-config="true" duration-ms="0" started-at="2020-06-12T08:10:44Z" finished-at="2020-06-12T08:10:44Z">
          <reporter-output>
          </reporter-output>
        </test-method> <!-- afterClass -->
      </class> <!-- testCases.order.TC_Recent_Phone_Number -->
    </test> <!-- Default test -->
  </suite> <!-- Default suite -->
</testng-results>
